<?xml version="1.0"?>
<robot xmlns:xacro="http://wiki.ros.org/xacro">
  <!--
    Convenience wrapper for the 'ur_robot' macro which provides default values
    for the various "parameters files" parameters for a UR5.

    This file can be used when composing a more complex scene with one or more
    UR5 robots.

    While the generic 'ur_robot' macro could also be used, it would require
    the user to provide values for all parameters, as that macro does not set
    any model-specific defaults (not even for the generic parameters, such as
    the visual and physical parameters and joint limits).

    Refer to the main 'ur_macro.xacro' in this package for information about
    use, contributors and limitations.

    NOTE: users will most likely want to override *at least* the
          'kinematics_parameters_file' parameter. Otherwise, a default kinematic
          model will be used, which will almost certainly not correspond to any
          real robot.
  -->

  <xacro:include filename="$(find turbo_description)/urdf/inc/left_ur_transmissions.xacro" />
  <xacro:include filename="$(find turbo_description)/urdf/inc/left_ur_common.xacro" />

  <xacro:macro name="ur5_robot" params="
    joint_limits_parameters_file:='$(find ur_description)/config/ur5/joint_limits.yaml'
    left_kinematics_parameters_file:='$(find turbo_description)/config/left_arm_calibration.yaml'
    physical_parameters_file:='$(find ur_description)/config/ur5/physical_parameters.yaml'
    visual_parameters_file:='$(find ur_description)/config/ur5/visual_parameters.yaml'
    transmission_hw_interface:=hardware_interface/PositionJointInterface
    safety_limits:=false
    safety_pos_margin:=0.15
    safety_k_position:=20"
  >
    <!-- Load configuration data from the provided .yaml files -->
    <xacro:read_model_data
      joint_limits_parameters_file="${joint_limits_parameters_file}" 
      left_kinematics_parameters_file="${left_kinematics_parameters_file}"
      physical_parameters_file="${physical_parameters_file}"
      visual_parameters_file="${visual_parameters_file}"/>
    
    
    <!-- Add URDF transmission elements (for ros_control) -->
    <xacro:ur_arm_transmission prefix="left_" hw_interface="${transmission_hw_interface}" />


    <link name="left_base_link"/>
  
    <link name="left_base_link_inertia">
      <visual>
        <origin xyz="0 0 0" rpy="0 0 ${pi}"/>
        <geometry>
          <mesh filename="${base_visual_mesh}"/>
        </geometry>
        <material name="${base_visual_material_name}">
          <color rgba="${base_visual_material_color}"/>
        </material>
      </visual>
      <collision>
        <origin xyz="0 0 0" rpy="0 0 ${pi}"/>
        <geometry>
          <mesh filename="${base_collision_mesh}"/>
        </geometry>
      </collision>
      <xacro:cylinder_inertial radius="${base_inertia_radius}" length="${base_inertia_length}" mass="${base_mass}">
        <origin xyz="0 0 0" rpy="0 0 0" />
      </xacro:cylinder_inertial>
    </link>

    <link name="left_shoulder_link">
      <visual>
        <origin xyz="0 0 0" rpy="0 0 ${pi}"/>
        <geometry>
          <mesh filename="${shoulder_visual_mesh}"/>
        </geometry>
        <material name="${shoulder_visual_material_name}">
          <color rgba="${shoulder_visual_material_color}"/>
        </material>
      </visual>
      <collision>
        <origin xyz="0 0 0" rpy="0 0 ${pi}"/>
        <geometry>
          <mesh filename="${shoulder_collision_mesh}"/>
        </geometry>
      </collision>
      <xacro:cylinder_inertial radius="${shoulder_inertia_radius}" length="${shoulder_inertia_length}" mass="${shoulder_mass}">
        <origin xyz="0 0 0" rpy="0 0 0" />
      </xacro:cylinder_inertial>
    </link>
        
    <link name="left_upper_arm_link">
      <visual>
        <origin xyz="0 0 ${shoulder_offset}" rpy="${pi/2} 0 ${-pi/2}"/>
        <geometry>
          <mesh filename="${upper_arm_visual_mesh}"/>
        </geometry>
        <material name="${upper_arm_visual_material_name}">
          <color rgba="${upper_arm_visual_material_color}"/>
        </material>
      </visual>
      <collision>
        <origin xyz="0 0 ${shoulder_offset}" rpy="${pi/2} 0 ${-pi/2}"/>
        <geometry>
          <mesh filename="${upper_arm_collision_mesh}"/>
        </geometry>
      </collision>
      <xacro:cylinder_inertial radius="${upperarm_inertia_radius}" length="${upperarm_inertia_length}" mass="${upper_arm_mass}">
        <origin xyz="${-0.5 * upperarm_inertia_length} 0.0 ${upper_arm_inertia_offset}" rpy="0 ${pi/2} 0" />
      </xacro:cylinder_inertial>
    </link>
    
    <link name="left_forearm_link">
      <visual>
        <origin xyz="0 0 ${elbow_offset}" rpy="${pi/2} 0 ${-pi/2}"/>
        <geometry>
          <mesh filename="${forearm_visual_mesh}"/>
        </geometry>
        <material name="${forearm_visual_material_name}">
          <color rgba="${forearm_visual_material_color}"/>
        </material>
      </visual>
      <collision>
        <origin xyz="0 0 ${elbow_offset}" rpy="${pi/2} 0 ${-pi/2}"/>
        <geometry>
          <mesh filename="${forearm_collision_mesh}"/>
        </geometry>
      </collision>
      <xacro:cylinder_inertial radius="${forearm_inertia_radius}" length="${forearm_inertia_length}"  mass="${forearm_mass}">
        <origin xyz="${-0.5 * forearm_inertia_length} 0.0 ${elbow_offset}" rpy="0 ${pi/2} 0" />
      </xacro:cylinder_inertial>
    </link>
    
    <link name="left_wrist_1_link">
      <visual>
        <!-- TODO: Move this to a parameter -->
        <origin xyz="0 0 ${wrist_1_visual_offset}" rpy="${pi/2} 0 0"/>
        <geometry>
          <mesh filename="${wrist_1_visual_mesh}"/>
        </geometry>
        <material name="${wrist_1_visual_material_name}">
          <color rgba="${wrist_1_visual_material_color}"/>
        </material>
      </visual>
      <collision>
        <origin xyz="0 0 ${wrist_1_visual_offset}" rpy="${pi/2} 0 0"/>
        <geometry>
          <mesh filename="${wrist_1_collision_mesh}"/>
        </geometry>
      </collision>
      <xacro:cylinder_inertial radius="${wrist_1_inertia_radius}" length="${wrist_1_inertia_length}"  mass="${wrist_1_mass}">
        <origin xyz="0 0 0" rpy="0 0 0" />
      </xacro:cylinder_inertial>
    </link>
    
    <link name="left_wrist_2_link">
      <visual>
        <origin xyz="0 0 ${wrist_2_visual_offset}" rpy="0 0 0"/>
        <geometry>
          <mesh filename="${wrist_2_visual_mesh}"/>
        </geometry>
        <material name="${wrist_2_visual_material_name}">
          <color rgba="${wrist_2_visual_material_color}"/>
        </material>
      </visual>
      <collision>
        <origin xyz="0 0 ${wrist_2_visual_offset}" rpy="0 0 0"/>
        <geometry>
          <mesh filename="${wrist_2_collision_mesh}"/>
        </geometry>
      </collision>
      <xacro:cylinder_inertial radius="${wrist_2_inertia_radius}" length="${wrist_2_inertia_length}"  mass="${wrist_2_mass}">
        <origin xyz="0 0 0" rpy="0 0 0" />
      </xacro:cylinder_inertial>
    </link>
    
    <link name="left_wrist_3_link">
      <visual>
        <origin xyz="0 0 ${wrist_3_visual_offset}" rpy="${pi/2} 0 0"/>
        <geometry>
          <mesh filename="${wrist_3_visual_mesh}"/>
        </geometry>
        <material name="${wrist_3_visual_material_name}">
          <color rgba="${wrist_3_visual_material_color}"/>
        </material>
      </visual>
      <collision>
        <origin xyz="0 0 ${wrist_3_visual_offset}" rpy="${pi/2} 0 0"/>
        <geometry>
          <mesh filename="${wrist_3_collision_mesh}"/>
        </geometry>
      </collision>
      <xacro:cylinder_inertial radius="${wrist_3_inertia_radius}" length="${wrist_3_inertia_length}"  mass="${wrist_3_mass}">
        <origin xyz="0.0 0.0 ${-0.5 * wrist_3_inertia_length}" rpy="0 0 0" />
      </xacro:cylinder_inertial>
    </link>


    <!-- joints: main serial chain -->
    <joint name="left_base_link-base_link_inertia" type="fixed">
      <parent link="left_base_link" />
      <child link="left_base_link_inertia" />
      <!-- 'base_link' is REP-103 aligned (so X+ forward), while the internal
           frames of the robot/controller have X+ pointing backwards.
           Use the joint between 'base_link' and 'base_link_inertia' (a dummy
           link/frame) to introduce the necessary rotation over Z (of pi rad).
      -->
      <origin xyz="0 0 0" rpy="0 0 0" />
    </joint>
    
    <joint name="left_shoulder_pan_joint" type="revolute">
      <parent link="left_base_link_inertia" />
      <child link="left_shoulder_link" />
      <origin xyz="${left_shoulder_x} ${left_shoulder_y} ${left_shoulder_z}" rpy="${left_shoulder_roll} ${left_shoulder_pitch} ${left_shoulder_yaw}" />
      <axis xyz="0 0 1" />
      <limit lower="${shoulder_pan_lower_limit}" upper="${shoulder_pan_upper_limit}"
        effort="${shoulder_pan_effort_limit}" velocity="${shoulder_pan_velocity_limit}"/>
      <xacro:if value="${safety_limits}">
         <safety_controller soft_lower_limit="${shoulder_pan_lower_limit + safety_pos_margin}" soft_upper_limit="${shoulder_pan_upper_limit - safety_pos_margin}" k_position="${safety_k_position}" k_velocity="0.0"/>
      </xacro:if>
      <dynamics damping="0" friction="0"/>
    </joint>

    <joint name="left_shoulder_lift_joint" type="revolute">
      <parent link="left_shoulder_link" />
      <child link="left_upper_arm_link" />
      <origin xyz="${left_upper_arm_x} ${left_upper_arm_y} ${left_upper_arm_z}" rpy="${left_upper_arm_roll} ${left_upper_arm_pitch} ${left_upper_arm_yaw}" />
      <axis xyz="0 0 1" />
      <limit lower="${shoulder_lift_lower_limit}" upper="${shoulder_lift_upper_limit}"
        effort="${shoulder_lift_effort_limit}" velocity="${shoulder_lift_velocity_limit}"/>
      <xacro:if value="${safety_limits}">
         <safety_controller soft_lower_limit="${shoulder_lift_lower_limit + safety_pos_margin}" soft_upper_limit="${shoulder_lift_upper_limit - safety_pos_margin}" k_position="${safety_k_position}" k_velocity="0.0"/>
      </xacro:if>
      <dynamics damping="0" friction="0"/>
    </joint>

    <joint name="left_elbow_joint" type="revolute">
      <parent link="left_upper_arm_link" />
      <child link="left_forearm_link" />
      <origin xyz="${left_forearm_x} ${left_forearm_y} ${left_forearm_z}" rpy="${left_forearm_roll} ${left_forearm_pitch} ${left_forearm_yaw}" />
      <axis xyz="0 0 1" />
      <limit lower="${elbow_joint_lower_limit}" upper="${elbow_joint_upper_limit}"
        effort="${elbow_joint_effort_limit}" velocity="${elbow_joint_velocity_limit}"/>
      <xacro:if value="${safety_limits}">
         <safety_controller soft_lower_limit="${elbow_joint_lower_limit + safety_pos_margin}" soft_upper_limit="${elbow_joint_upper_limit - safety_pos_margin}" k_position="${safety_k_position}" k_velocity="0.0"/>
      </xacro:if>
      <dynamics damping="0" friction="0"/>
    </joint>

    <joint name="left_wrist_1_joint" type="revolute">
      <parent link="left_forearm_link" />
      <child link="left_wrist_1_link" />
      <origin xyz="${left_wrist_1_x} ${left_wrist_1_y} ${left_wrist_1_z}" rpy="${left_wrist_1_roll} ${left_wrist_1_pitch} ${left_wrist_1_yaw}" />
      <axis xyz="0 0 1" />
      <limit lower="${wrist_1_lower_limit}" upper="${wrist_1_upper_limit}"
        effort="${wrist_1_effort_limit}" velocity="${wrist_1_velocity_limit}"/>
      <xacro:if value="${safety_limits}">
         <safety_controller soft_lower_limit="${wrist_1_lower_limit + safety_pos_margin}" soft_upper_limit="${wrist_1_upper_limit - safety_pos_margin}" k_position="${safety_k_position}" k_velocity="0.0"/>
      </xacro:if>
      <dynamics damping="0" friction="0"/>
    </joint>

    <joint name="left_wrist_2_joint" type="revolute">
      <parent link="left_wrist_1_link" />
      <child link="left_wrist_2_link" />
      <origin xyz="${left_wrist_2_x} ${left_wrist_2_y} ${left_wrist_2_z}" rpy="${left_wrist_2_roll} ${left_wrist_2_pitch} ${left_wrist_2_yaw}" />
      <axis xyz="0 0 1" />
      <limit lower="${wrist_2_lower_limit}" upper="${wrist_2_upper_limit}"
             effort="${wrist_2_effort_limit}" velocity="${wrist_2_velocity_limit}"/>
      <xacro:if value="${safety_limits}">
         <safety_controller soft_lower_limit="${wrist_2_lower_limit + safety_pos_margin}" soft_upper_limit="${wrist_2_upper_limit - safety_pos_margin}" k_position="${safety_k_position}" k_velocity="0.0"/>
      </xacro:if>
      <dynamics damping="0" friction="0"/>
    </joint>

    <joint name="left_wrist_3_joint" type="revolute">
      <parent link="left_wrist_2_link" />
      <child link="left_wrist_3_link" />
      <origin xyz="${left_wrist_3_x} ${left_wrist_3_y} ${left_wrist_3_z}" rpy="${left_wrist_3_roll} ${left_wrist_3_pitch} ${left_wrist_3_yaw}" />
      <axis xyz="0 0 1" />
      <limit lower="${wrist_3_lower_limit}" upper="${wrist_3_upper_limit}"
             effort="${wrist_3_effort_limit}" velocity="${wrist_3_velocity_limit}"/>
      <xacro:if value="${safety_limits}">
         <safety_controller soft_lower_limit="${wrist_3_lower_limit + safety_pos_margin}" soft_upper_limit="${wrist_3_upper_limit - safety_pos_margin}" k_position="${safety_k_position}" k_velocity="0.0"/>
      </xacro:if>
      <dynamics damping="0" friction="0"/>
    </joint>

    <!-- ROS-Industrial 'base' frame: base_link to UR 'Base' Coordinates transform -->
    <link name="left_base"/>
    <joint name="left_base_link-base_fixed_joint" type="fixed">
      <!-- Note the rotation over Z of pi radians: as base_link is REP-103
           aligned (ie: has X+ forward, Y+ left and Z+ up), this is needed
           to correctly align 'base' with the 'Base' coordinate system of
           the UR controller.
      -->
      <origin xyz="0 0 0" rpy="0 0 ${pi}"/>
      <parent link="left_base_link"/>
      <child link="left_base"/>
    </joint>

    <!-- ROS-Industrial 'flange' frame: attachment point for EEF models -->
    <link name="left_flange" />
    <joint name="left_wrist_3-flange" type="fixed">
      <parent link="left_wrist_3_link" />
      <child link="left_flange" />
      <origin xyz="0 0 0" rpy="0 ${-pi/2.0} ${-pi/2.0}" />
    </joint>

    <!-- ROS-Industrial 'tool0' frame: all-zeros tool frame -->
    <link name="left_tool0"/>
    <joint name="left_flange-tool0" type="fixed">
      <!-- default toolframe: X+ left, Y+ up, Z+ front -->
      <origin xyz="0 0 0" rpy="${pi/2.0} 0 ${pi/2.0}"/>
      <parent link="left_flange"/>
      <child link="left_tool0"/>
    </joint>

  </xacro:macro>
</robot>
